Workbook
Name communication: Overview!$J$4:$J$9
Name not_communicative_at_all: Overview!$J$7:$J$8

Sheet Overview
A1: Candidate name:
A2: Interviewer name:
A3: Date of technical interview
A4: Communication in English: | B4: Please assess English language proficiency... | J4: Please assess English language proficiency...
A5: Coding Task: | B5: Other | J5: Not assessed
A6: Coding Task description: | B6: Describe your coding task if "other" is selected above | J6: Not communicative at all
A7: Overall impression, with assessed seniority and ability to grow: | J7: Poor English / strong accent
A8: Template version | B8: 8.3.1 | J8: Good English / light accent | Q8: familiar | R8: junior
J9: Proficient
A12: Section | F12: Score | G12: Section result | H12: Enable / Disable section | M12: Enabled
A13: =Java!C8 -> 1. Coding task (just discuss possible solutions) | F13: =IF($H$13="Enabled",Java!E13,"-") -> - | G13: =IF($H$13="Enabled",Java!F13,"-") -> not assessed | H13: Enabled | M13: Disabled
A14: =Java!C14 -> 2. CS basics, Algorithms & Data structures | F14: =IF($H$14="Enabled",Java!E34,"-") -> - | G14: =IF($H$14="Enabled",Java!F34,"-") -> not assessed | H14: Enabled
A15: =Java!C35 -> 3. Collections | F15: =IF($H$15="Enabled",Java!E48,"-") -> - | G15: =IF($H$15="Enabled",Java!F48,"-") -> not assessed | H15: Enabled
A16: =Java!C49 -> 4. Java basics | F16: =IF($H$16="Enabled",Java!E64,"-") -> - | G16: =IF($H$16="Enabled",Java!F64,"-") -> not assessed | H16: Enabled
A17: =Java!C65 -> 5. Exceptions | F17: =IF($H$17="Enabled",Java!E78,"-") -> - | G17: =IF($H$17="Enabled",Java!F78,"-") -> not assessed | H17: Enabled
A18: =Java!C79 -> 6. Memory & GC | F18: =IF($H$18="Enabled",Java!E97,"-") -> - | G18: =IF($H$18="Enabled",Java!F97,"-") -> not assessed | H18: Enabled
A19: =Java!C98 -> 7. Modern Java Versions Specifics | F19: =IF($H$19="Enabled",Java!E115,"-") -> - | G19: =IF($H$19="Enabled",Java!F115,"-") -> not assessed | H19: Enabled
A20: =Java!C116 -> 8. Multithreading | F20: =IF($H$20="Enabled",Java!E138,"-") -> - | G20: =IF($H$20="Enabled",Java!F138,"-") -> not assessed | H20: Enabled
A21: =Java!C139 -> 9. OOP | F21: =IF($H$21="Enabled",Java!E145,"-") -> - | G21: =IF($H$21="Enabled",Java!F145,"-") -> not assessed | H21: Enabled
A22: =Java!C146 -> 10. Design patterns | F22: =IF($H$22="Enabled",Java!E158,"-") -> - | G22: =IF($H$22="Enabled",Java!F158,"-") -> not assessed | H22: Enabled
A23: =Java!C159 -> 11. Clean Code | F23: =IF($H$23="Enabled",Java!E165,"-") -> - | G23: =IF($H$23="Enabled",Java!F165,"-") -> not assessed | H23: Enabled
A24: =Java!C166 -> 12. Testing | F24: =IF($H$24="Enabled",Java!E175,"-") -> - | G24: =IF($H$24="Enabled",Java!F175,"-") -> not assessed | H24: Enabled
A25: =Java!C176 -> 13. Spring | F25: =IF($H$25="Enabled",Java!E190,"-") -> - | G25: =IF($H$25="Enabled",Java!F190,"-") -> not assessed | H25: Enabled
A26: =Java!C191 -> 14. Spring Boot | F26: =IF($H$26="Enabled",Java!E199,"-") -> - | G26: =IF($H$25="Enabled",Java!F199,"-") -> not assessed | H26: Enabled
A27: =Java!C200 -> 15. Microservices | F27: =IF($H$27="Enabled",Java!E208,"-") -> - | G27: =IF($H$27="Enabled",Java!F208,"-") -> not assessed | H27: Enabled
A28: =Java!C209 -> 16. Hibernate / JPA | F28: =IF($H$28="Enabled",Java!E235,"-") -> - | G28: =IF($H$28="Enabled",Java!F235,"-") -> not assessed | H28: Enabled
A29: =Java!C236 -> 17. SQL | F29: =IF($H$29="Enabled",Java!E264,"-") -> - | G29: =IF($H$29="Enabled",Java!F264,"-") -> not assessed | H29: Enabled
A30: =Java!C265 -> 18. Unix and networking | F30: =IF($H$30="Enabled",Java!E274,"-") -> - | G30: =IF($H$30="Enabled",Java!F274,"-") -> not assessed | H30: Enabled
A31: =Java!C275 -> 19. JMS / Kafka | F31: =IF($H$31="Enabled",Java!E288,"-") -> - | G31: =IF($H$31="Enabled",Java!F288,"-") -> not assessed | H31: Enabled
A32: =Java!C289 -> 20. Cloud | F32: - | G32: =IF($H$32="Enabled",Java!F290,"-") -> not assessed | H32: Enabled
G33: =IF(_xlfn.IFNA(MATCH("not assessed",G13:G32,0),0)>0,"Assessement incomplete!","") -> Assessement incomplete!

Sheet Java
G1: not assessed
C2: Mandatory sections marked with this colour must be assessed. If a candidate has no experience, select "Insufficient" against any question. All other sections should be assessed if candidate claims he has experience. Feel free to use Custom Question to ask your onw questions - and specify what question was asked. | F2: 1 | G2: insufficient | H2: Candidate is ignorant about the subject, knows little but its name , can't recall any details or has some misbeliefs about it
F3: 2 | G3: junior | H3: Candidate has basic idea about the subject, able to use it in some simple scenario, lacks details about some obvious (regular) scenario
F4: 3 | G4: regular | H4: Candidate has knowledge sufficient to use the subject in most everyday scenario, may lack details about some advanced usage scenario, but no misbeliefs
F5: 4 | G5: senior | H5: Candidate has knowledge sufficient to use the subject in all advanced scenario discussed
F6: 5 | G6: expert | H6: Candidate has comprehensive knowledge on the subject, can teach the subject or act as an expert on it
G7: not assessed
C8: 1. Coding task (just discuss possible solutions) | D8: max | E8: Score | F8: Seniority | G8: Comments (if answered partially)
A9: M | B9: All | C9: Coding task (if over phone, discuss only possible solution) | D9: 5 | E9: =IF(F9=$G$2, 1, IF(F9=$G$3,2, IF(F9=$G$4,3,IF(F9=$G$5,4,IF(F9=$G$6,5,IF(F9=$G$7,0)))))) -> 0 | F9: not assessed
A10: M | C10: Complexity of solved coding task | D10: 5 | E10: =IF(F10=$G$2, 1, IF(F10=$G$3,2, IF(F10=$G$4,3,IF(F10=$G$5,4,IF(F10=$G$6,5,IF(F10=$G$7,0)))))) -> 0 | F10: not assessed
A11: M | C11: Coding task optimization | D11: 5 | E11: =IF(F11=$G$2, 1, IF(F11=$G$3,2, IF(F11=$G$4,3,IF(F11=$G$5,4,IF(F11=$G$6,5,IF(F11=$G$7,0)))))) -> 0 | F11: not assessed
C12: Custom question | D12: 5 | E12: =IF(F12=$G$2, 1, IF(F12=$G$3,2, IF(F12=$G$4,3,IF(F12=$G$5,4,IF(F12=$G$6,5,IF(F12=$G$7,0)))))) -> 0 | F12: not assessed
D13: =IF(B13="", D12, IF(OR(B13="Junior", B13="Regular"), 3, 5)) -> 5 | E13: =IFERROR(AVERAGEIF(E9:E12, "<>0"),"-") -> - | F13: =IFERROR(LOOKUP(E13,Technical!$A$2:$B$8,Technical!$C$2:$C$8),"not assessed") -> not assessed
C14: 2. CS basics, Algorithms & Data structures | D14: =IF(B14="", D13, IF(OR(B14="Junior", B14="Regular"), 3, 5)) -> 5
B15: Junior | C15: Data structures e.g. Stack vs queue | D15: =IF(B15="", D14, IF(OR(B15="Junior", B15="Regular"), 3, 5)) -> 3 | E15: =IF(F15=$G$2, 1, IF(F15=$G$3,2, IF(F15=$G$4,3,IF(F15=$G$5,4,IF(F15=$G$6,5,IF(F15=$G$7,0)))))) -> 0 | F15: not assessed | J15: Stacks A stack is a linear data structure that follows the Last In, First Out (LIFO) principle. This means that the last element added to the stack is the first one to be removed. It can be visualized as a pile of plates where you can only add or remove the top plate. A queue is a linear data structure that follows the First In, First Out (FIFO) principle. This means that the first element added to the queue is the first one to be removed. It can be visualized as a line of people waiting for a service, where the first person in line is the first to be served.
C16: Boolean operations, short circuits in Boolean operations | D16: =IF(B16="", D15, IF(OR(B16="Junior", B16="Regular"), 3, 5)) -> 3 | E16: =IF(F16=$G$2, 1, IF(F16=$G$3,2, IF(F16=$G$4,3,IF(F16=$G$5,4,IF(F16=$G$6,5,IF(F16=$G$7,0)))))) -> 0 | F16: not assessed
A17: M | C17: Complexity of algorithms, big O notation (can be discussed during coding task) | D17: =IF(B17="", D16, IF(OR(B17="Junior", B17="Regular"), 3, 5)) -> 3 | E17: =IF(F17=$G$2, 1, IF(F17=$G$3,2, IF(F17=$G$4,3,IF(F17=$G$5,4,IF(F17=$G$6,5,IF(F17=$G$7,0)))))) -> 0 | F17: not assessed
A18: At least one is mandatory | C18: Trees, graphs and ways to traverse graph | D18: =IF(B18="", D17, IF(OR(B18="Junior", B18="Regular"), 3, 5)) -> 3 | E18: =IF(F18=$G$2, 1, IF(F18=$G$3,2, IF(F18=$G$4,3,IF(F18=$G$5,4,IF(F18=$G$6,5,IF(F18=$G$7,0)))))) -> 0 | F18: not assessed | I18: The tree data structure is a type of graph. A tree has a root node (top node) that will have a relationship with its child nodes. The path that connects the root node to the child nodes is called a branch. The leaf node is the node that doesn’t have any children and is not the root node. In algorithms, you will see a lot of the nomenclature height. Height in trees is the number of nodes from the highest branch to the root node. Another keyword is the depth of a tree which means the count of nodes from a specific node to the root node. A graph is a data structure for storing connected data such as a network of people on a social media platform. There are two possible ways to traverse a graph: depth-first traversal and breadth-first traversal. A depth-first traversal starts at an arbitrary root vertex and explores vertices as deep as possible along each branch before exploring vertices at the same level. breadth-first traversal starts at an arbitrary root vertex and explores all neighboring vertices at the same level before going deeper in the graph.
C19: Sorting algorithms | D19: =IF(B19="", D18, IF(OR(B19="Junior", B19="Regular"), 3, 5)) -> 3 | E19: =IF(F19=$G$2, 1, IF(F19=$G$3,2, IF(F19=$G$4,3,IF(F19=$G$5,4,IF(F19=$G$6,5,IF(F19=$G$7,0)))))) -> 0 | F19: not assessed | I19: Bubble Sort is the simplest sorting algorithm that works by repeatedly swapping the adjacent elements if they are in the wrong order. This algorithm is not suitable for large data sets as its average and worst-case time complexity are quite high. The Merge Sort algorithm is a divide-and-conquer algorithm that sorts an array by first breaking it down into smaller arrays, and then building the array back together the correct way so that it is sorted. QuickSort is a sorting algorithm based on the Divide and Conquer that picks an element as a pivot and partitions the given array around the picked pivot by placing the pivot in its correct position in the sorted array.
B20: Regular | C20: Recursion, tail recursion, mutual recursion | D20: =IF(B20="", D19, IF(OR(B20="Junior", B20="Regular"), 3, 5)) -> 3 | E20: =IF(F20=$G$2, 1, IF(F20=$G$3,2, IF(F20=$G$4,3,IF(F20=$G$5,4,IF(F20=$G$6,5,IF(F20=$G$7,0)))))) -> 0 | F20: not assessed | I20: Recursion is the process where a function self-calls itself to find the result. The base condition acts as the breakpoint to the self-calling process. Tail Recursion A recursive function is a tail recursive when a recursive call is the last thing executed by the function. Mutual Recursion This happens where one method, say method A, calls another method B, which then calls method A. This involves two or more methods that eventually create a circular call sequence. Direct and indirect recursion A function fun is called direct recursive if it calls the same function fun. A function fun is called indirect recursive if it calls another function say fun_new and fun_new calls fun directly or indirectly.
C21: Binary tree / Self balanced trees (Red-black tree, AVL, Splay) | D21: =IF(B21="", D20, IF(OR(B21="Junior", B21="Regular"), 3, 5)) -> 3 | E21: =IF(F21=$G$2, 1, IF(F21=$G$3,2, IF(F21=$G$4,3,IF(F21=$G$5,4,IF(F21=$G$6,5,IF(F21=$G$7,0)))))) -> 0 | F21: not assessed | I21: Binary Tree A tree in which each node (parent) has at most two-child nodes (left and right) is called binary tree. The top most node is called the root node. In a binary tree a node contains the data and the pointer (address) of the left and right child node. mainly used for sorting and searching because they store data in hierarchical form. A red-black tree is a self-balancing binary search tree, that is, a binary search tree that automatically maintains some balance. Each node is assigned a color (red or black). A set of rules specifies how these colors must be arranged (e.g., a red node may not have red children) AVL tree is another self-balancing BST(Binary Search Tree) in Java. In the AVL tree, the difference between heights of the right and left subtree doesn't exceed one for all nodes. It takes O(h) time to perform the search, max, min, insert, and delete BST operations. A splay tree is a self-balancing tree, but AVL and Red-Black trees are also self-balancing trees then. What makes the splay tree unique two trees. It has one extra property that makes it unique is splaying. A splay tree contains the same operations as a Binary search tree, i.e., Insertion, deletion and searching, but it also contains one more operation, i.e., splaying. So. all the operations in the splay tree are followed by splaying.All normal operations on a binary search tree are combined with one basic operation, called splaying. Splaying the tree for a certain element rearranges the tree so that the element is placed at the root of the tree.
C22: Search in binary tree | D22: =IF(B22="", D21, IF(OR(B22="Junior", B22="Regular"), 3, 5)) -> 3 | E22: =IF(F22=$G$2, 1, IF(F22=$G$3,2, IF(F22=$G$4,3,IF(F22=$G$5,4,IF(F22=$G$6,5,IF(F22=$G$7,0)))))) -> 0 | F22: not assessed | I22: Depth-first search is a type of traversal that goes deep as much as possible in every child before exploring the next sibling. There are several ways to perform a depth-first search: in-order, pre-order and post-order. The in-order traversal consists of first visiting the left sub-tree, then the root node, and finally the right sub-tree. Pre-order traversal visits first the root node, then the left sub-tree, and finally the right sub-tree. Post-order traversal visits the left sub-tree, the right subt-ree, and the root node at the end Breadth-First Search This kind of traversal is also called level-order, and visits all the levels of the tree starting from the root, and from left to right.
C23: Linear-time sorting. (count sort) | D23: =IF(B23="", D22, IF(OR(B23="Junior", B23="Regular"), 3, 5)) -> 3 | E23: =IF(F23=$G$2, 1, IF(F23=$G$3,2, IF(F23=$G$4,3,IF(F23=$G$5,4,IF(F23=$G$6,5,IF(F23=$G$7,0)))))) -> 0 | F23: not assessed | I23: Linear time sorting is a subset of sorting algorithms with a significant advantage: they can sort a given set of elements in linear time, the runtime increases linearly with the input size. The best-known linear time sorting algorithm is descending sort. Computational sorting is particularly efficient when the range of input elements is known and relatively small. This eliminates the need to compare elements, the main time-consuming operation in many other sorting algorithms. | Q23: 1 find max num 2 create array with max size 3 fill occurrences of each num in origina array 4 sum occurrences: index 0 equal 1 then 1. index 1 equal 3 plus index 0 equal 1 sum is equal 4, index 2 equal 0 plus index 1 sum equal 4, index 3 equal 2 plus index2 sum equal 6 5 for each element in the original array look in count array for its next position: 1 starts in position 1, then it is added in the output array in index 1, count array index 1 plus1 so it is now 2 0, starts in index 0 according with count array, so added in index 0 of output array, count array index 0 value is now 1. 3 starts in index4 according to count array, add 3 at index 4 in output array, index 3of count array is now equal 5 1 starts now in index 2, so a 1 is added at index 2 in output array, index 1 is now equal to 3 in count array 3 starts now at index 5, in output array index 5 we add a 3, index 3 is now equal to 6 in count array 1 is now equal to 3 in count array, we go to index 3 in output array and add a 1, 1 is now equal to 4 in count array
C24: Sorting of linked list. | D24: =IF(B24="", D23, IF(OR(B24="Junior", B24="Regular"), 3, 5)) -> 3 | E24: =IF(F24=$G$2, 1, IF(F24=$G$3,2, IF(F24=$G$4,3,IF(F24=$G$5,4,IF(F24=$G$6,5,IF(F24=$G$7,0)))))) -> 0 | F24: not assessed | J24: For linked lists, Merge Sort is often the best choice because: Merge Sort guarantees a time complexity of O(nlogn) in the average, best, and worst cases. Merge Sort is Stable Merge Sort naturally fits well with Linked List because it traverses items in sequential manner (no random access) When we compare linked list implementation with the array implementation we can notice that the linked list implementation does not require extra space to merge because linked list allows insertion and deletion in the middle in O(1) time.
B25: Senior | C25: Prefix and suffix trees | D25: 5 | E25: =IF(F25=$G$2, 1, IF(F25=$G$3,2, IF(F25=$G$4,3,IF(F25=$G$5,4,IF(F25=$G$6,5,IF(F25=$G$7,0)))))) -> 0 | F25: not assessed | J25: prefix tree or trie. is an ordered tree structure, which takes advantage of the keys that it stores – usually strings. In a trie, every node (except the root node) stores one character or a digit. By traversing the trie down from the root node to a particular node n, a common prefix of characters or digits can be formed which is shared by other branches of the trie as well. | V25: A suffix tree is simply a compressed suffix trie. What this means is that, by joining the edges, we can store a group of characters and thereby reduce the storage space significantly. A suffix tree also stores the position of the suffix in the leaf node. For example, BANANA$ is a suffix starting from the seventh position. Hence, its value will be six using zero-based numbering. Likewise, A->BANANA$ is another suffix starting at position five,
C26: Describe heap | D26: =IF(B25="", D25, IF(OR(B25="Junior", B25="Regular"), 3, 5)) -> 5 | E26: =IF(F26=$G$2, 1, IF(F26=$G$3,2, IF(F26=$G$4,3,IF(F26=$G$5,4,IF(F26=$G$6,5,IF(F26=$G$7,0)))))) -> 0 | F26: not assessed | I26: Heap space is used for the dynamic memory allocation of Java objects and JRE classes at runtime. New objects are always created in heap space, and the references to these objects are stored in stack memory. These objects have global access and we can access them from anywhere in the application. Unlike stack, a heap isn’t threadsafe and needs to be guarded by properly synchronizing the code. If heap space is full, Java throws java.lang.OutOfMemoryError. Heap memory is used by all the parts of the application whereas stack memory is used only by one thread of execution. Whenever an object is created, it’s always stored in the Heap space and stack memory contains the reference to it. Stack memory only contains local primitive variables and reference variables to objects in heap space. Stack memory is short-lived whereas heap memory lives from the start till the end of application execution. When stack memory is full, Java runtime throws java.lang.StackOverFlowError whereas if heap memory is full, it throws java.lang.OutOfMemoryError: Java Heap Space error.
C27: Greedy Algorithm | D27: =IF(B27="", D26, IF(OR(B27="Junior", B27="Regular"), 3, 5)) -> 5 | E27: =IF(F27=$G$2, 1, IF(F27=$G$3,2, IF(F27=$G$4,3,IF(F27=$G$5,4,IF(F27=$G$6,5,IF(F27=$G$7,0)))))) -> 0 | F27: not assessed | J27: Greedy algorithms are a class of algorithms that make locally optimal choices at each step with the hope of finding a global optimum solution. In these algorithms, decisions are made based on the information available at the current moment without considering the consequences of these decisions in the future. The key idea is to select the best possible choice at each step, leading to a solution that may not always be the most optimal but is often good enough for many problems.It operates on the principle of “taking the best option now” without considering the long-term consequences.
C28: NP-complete algorithms | D28: =IF(B28="", D27, IF(OR(B28="Junior", B28="Regular"), 3, 5)) -> 5 | E28: =IF(F28=$G$2, 1, IF(F28=$G$3,2, IF(F28=$G$4,3,IF(F28=$G$5,4,IF(F28=$G$6,5,IF(F28=$G$7,0)))))) -> 0 | F28: not assessed | J28: NP stands for Non-deterministic Polynomial time. This means that the problem can be solved in Polynomial time using a Non-deterministic Turing machine (like a regular Turing machine but also including a non-deterministic "choice" function). Basically, a solution has to be testable in poly time. If that's the case, and a known NP problem can be solved using the given problem with modified input (an NP problem can be reduced to the given problem) then the problem is NP complete.
C29: Map/reduce and divide and conquer approach in solving tasks | D29: =IF(B29="", D28, IF(OR(B29="Junior", B29="Regular"), 3, 5)) -> 5 | E29: =IF(F29=$G$2, 1, IF(F29=$G$3,2, IF(F29=$G$4,3,IF(F29=$G$5,4,IF(F29=$G$6,5,IF(F29=$G$7,0)))))) -> 0 | F29: not assessed | J29: MapReduce is a programming model used for efficient processing in parallel over large data-sets in a distributed manner. The data is first split and then combined to produce the final result. | N29: A divide-and-conquer algorithm recursively breaks down a problem into two or more sub-problems of the same or related type, until these become simple enough to be solved directly. The solutions to the sub-problems are then combined to give a solution to the original problem.
C30: Dynamic programming | D30: =IF(B30="", D29, IF(OR(B30="Junior", B30="Regular"), 3, 5)) -> 5 | E30: =IF(F30=$G$2, 1, IF(F30=$G$3,2, IF(F30=$G$4,3,IF(F30=$G$5,4,IF(F30=$G$6,5,IF(F30=$G$7,0)))))) -> 0 | F30: not assessed | J30: Dynamic Programming is a method used in mathematics and computer science to solve complex problems by breaking them down into simpler subproblems. By solving each subproblem only once and storing the results, it avoids redundant computations, leading to more efficient solutions for a wide range of problems. How Does Dynamic Programming (DP) Work? Identify Subproblems: Divide the main problem into smaller, independent subproblems. Store Solutions: Solve each subproblem and store the solution in a table or array. Build Up Solutions: Use the stored solutions to build up the solution to the main problem. Avoid Redundancy: By storing solutions, DP ensures that each subproblem is solved only once, reducing computation time. ivide and conquer is a strategy for separating a problem into smaller sections and addressing each one separately. In contrast, dynamic programming is a strategy for solving larger issues by breaking them down into smaller pieces.
C31: How would you fix a cyclic dependency | D31: =IF(B31="", D30, IF(OR(B31="Junior", B31="Regular"), 3, 5)) -> 5 | E31: =IF(F31=$G$2, 1, IF(F31=$G$3,2, IF(F31=$G$4,3,IF(F31=$G$5,4,IF(F31=$G$6,5,IF(F31=$G$7,0)))))) -> 0 | F31: not assessed | J31: Cyclic dependencies occur when two or more components depend on each other directly or indirectly. Cyclic dependencies introduce several main drawbacks: Tight Coupling: Components become tightly coupled, making it difficult to change or reuse them independently. Unintended Side Effects: Changes in one component can have unexpected and difficult-to-debug side effects on other components within the cycle. By applying the Dependency Inversion Principle (DIP), you can break circular dependencies. For example, we can fix the circular dependency in our example above by introducing a new module that serves as a stable interface both the app module and module2 can depend on.
C32: What is the difference between static and dynamic typing? Duck typing? | D32: 5 | E32: =IF(F32=$G$2, 1, IF(F32=$G$3,2, IF(F32=$G$4,3,IF(F32=$G$5,4,IF(F32=$G$6,5,IF(F32=$G$7,0)))))) -> 0 | F32: not assessed | J32: Static Typing Static typing is a typing system where variables are bound to a data type during compilation. Once a variable is assigned a data type it remains unchanged throughout the programs execution. This binding promotes type safety and detects errors at an early stage. One of the advantages of typing is ensuring type safety which reduces the chances of runtime errors caused by mismatches in data types. ex, java, c++ Dynamic Typing In contrast, dynamic typing allows variables to be bound to data types at runtime instead of during compilation. This flexibility enables concise code and ease of use. It compromises on type safety as a trade-off. ex: js Duck typing In computer programming, duck typing is an application of the duck test—"If it walks like a duck and it quacks like a duck, then it must be a duck"—to determine whether an object can be used for a particular purpose. With duck typing, an object is of a given type if it has all methods and properties required by that type
B33: All | C33: Custom question | D33: =IF(B33="", D31, IF(OR(B33="Junior", B33="Regular"), 3, 5)) -> 5 | E33: =IF(F33=$G$2, 1, IF(F33=$G$3,2, IF(F33=$G$4,3,IF(F33=$G$5,4,IF(F33=$G$6,5,IF(F33=$G$7,0)))))) -> 0 | F33: not assessed
D34: =IF(B34="", D33, IF(OR(B34="Junior", B34="Regular"), 3, 5)) -> 5 | E34: =IFERROR(AVERAGEIF(E15:E33, "<>0"),"-") -> - | F34: =IFERROR(LOOKUP(E34,Technical!$A$2:$B$8,Technical!$C$2:$C$8),"not assessed") -> not assessed
C35: 3. Collections | D35: =IF(B35="", D34, IF(OR(B35="Junior", B35="Regular"), 3, 5)) -> 5
A36: At least one is mandatory | B36: Regular | C36: General collection interfaces (Collection, Set, Map, List, Queue, SortedSet, SortedMap) | D36: =IF(B36="", D35, IF(OR(B36="Junior", B36="Regular"), 3, 5)) -> 3 | E36: =IF(F36=$G$2, 1, IF(F36=$G$3,2, IF(F36=$G$4,3,IF(F36=$G$5,4,IF(F36=$G$6,5,IF(F36=$G$7,0)))))) -> 0 | F36: not assessed | I36: Queue: The queue is an abstract data type or linear data structure from which elements can be inserted at the rear(back) of the queue and elements can be deleted from the front(head) of the queue. Deque: The double-ended queue is an abstract data type that generalizes a queue from which elements can be inserted or deleted either from both front(head) or rear(tail) ends. SortedSet: A Set that further provides a total ordering on its elements. The elements are ordered using their natural ordering, or by a Comparator typically provided at sorted set creation time. The set's iterator will traverse the set in ascending element order. Several additional operations are provided to take advantage of the ordering. This means that when you iterate the elements of a SortedSet the elements are iterated in the sorted order. SortedMap: The Java SortedMap interface, java.util.SortedMap, is a subtype of the java.util.Map interface, with the addition that the elements stored in a Java SortedMap map are sorted internally. This means you can iterate the elements stored in a SortedMap in the sort order. SortedMap sortedMap = new TreeMap(); Comparator comparator = new MyComparatorImpl(); SortedMap sortedMap = new TreeMap(comparator); the keys of a SortedMap are sorted iterate the keys in descending order rather than ascending order, use the sortedMap.descendingKeySet().iterator()
C37: Interfaces extending Collection. Is Map part of Collection interface | D37: =IF(B37="", D36, IF(OR(B37="Junior", B37="Regular"), 3, 5)) -> 3 | E37: =IF(F37=$G$2, 1, IF(F37=$G$3,2, IF(F37=$G$4,3,IF(F37=$G$5,4,IF(F37=$G$6,5,IF(F37=$G$7,0)))))) -> 0 | F37: not assessed
C38: Difference between ArrayList and LinkedList | D38: =IF(B38="", D37, IF(OR(B38="Junior", B38="Regular"), 3, 5)) -> 3 | E38: =IF(F38=$G$2, 1, IF(F38=$G$3,2, IF(F38=$G$4,3,IF(F38=$G$5,4,IF(F38=$G$6,5,IF(F38=$G$7,0)))))) -> 0 | F38: not assessed | J38: ArrayList nternally, ArrayList is using an array to implement the List interface. As arrays are fixed size in Java, ArrayList creates an array with some initial capacity. Along the way, if we need to store more items than that default capacity, it will replace that array with a new and more spacious one. Accessing items by their indices is where the ArrayList really shines. To retrieve an item at index i, we just have to return the item residing at the ith index from the backing array. Consequently, the time complexity for access by index operation is always O(1). , it’s actually a sensible choice when the number of reads is far more than the number of writes. LinkedList uses a collection of linked nodes to store and retrieve elements. the time complexity for the add operation is always O(1). LinkedList, as opposed to ArrayList, does not support fast random access. So, in order to find an element by index, we should traverse some portion of the list manually. LinkedLists are more suitable when the addition rate is much higher than the read rate. Also, it can be used in read-heavy scenarios when most of the time we want the first or last element. It’s worth mentioning that LinkedList also implements the Deque interface – supporting efficient access to both ends of the collection.
C39: Difference between Stack and Queue | D39: =IF(B39="", D38, IF(OR(B39="Junior", B39="Regular"), 3, 5)) -> 3 | E39: =IF(F39=$G$2, 1, IF(F39=$G$3,2, IF(F39=$G$4,3,IF(F39=$G$5,4,IF(F39=$G$6,5,IF(F39=$G$7,0)))))) -> 0 | F39: not assessed | J39: Stacks A stack is a linear data structure that follows the Last In, First Out (LIFO) principle. This means that the last element added to the stack is the first one to be removed. It can be visualized as a pile of plates where you can only add or remove the top plate. A queue is a linear data structure that follows the First In, First Out (FIFO) principle. This means that the first element added to the queue is the first one to be removed. It can be visualized as a line of people waiting for a service, where the first person in line is the first to be served.
C40: TreeSet vs TreeMap | D40: =IF(B40="", D39, IF(OR(B40="Junior", B40="Regular"), 3, 5)) -> 3 | E40: =IF(F40=$G$2, 1, IF(F40=$G$3,2, IF(F40=$G$4,3,IF(F40=$G$5,4,IF(F40=$G$6,5,IF(F40=$G$7,0)))))) -> 0 | F40: not assessed
...

Sheet Example Coding tasks
A1: Please select one of…
A2: Number of pairs in Array | B2: Write java function which calculates number of pairs in array. Pair is when two numbers added together, result is zero.
A3: Traverse tree | B3: Write java function to find some element in binary search tree
A4: Reverse List | B4: Write java function to reverse elements in one directional linked list
A5: Merge sorted arrays | B5: Having two separate sorted arrays, write java function merging these arrays in single sorted array without sorting it
A6: Find duplicate number in array | B6: An array contains numbers. Exactly one number is duplicated in the array. Write java function to find this duplicate | E6: We have an array {8,7,5,1,5,3,4}. As you can see there is exactly one number duplicated in the array (number 5). Write a java function to return this duplicate number (method is expected to return 5 as a result)
A7: Find number in matrix | B7: In a 2D matrix, every row ins increasingly sorted from left to right. Last number in each row is not greater then first number in next row. Write java function to check if there is a number in the matrix
A8: Find number of occurrences in array | B8: Write java function to find number of occurrences of some number in given array of numbers
A9: Other | B9: We have the following map of contacts, we want to take this map and return a list of all phones which exist in the map. (in this case we would expect to return a list with 6 phone numbers). Using java 8 stream operations. | E9: We have the following map: Map<String, List<String>> people = new HashMap<>(); people.put("John", Arrays.asList("555-1123", "555-3389")); people.put("Mary", Arrays.asList("555-2243", "555-5264")); people.put("Steve", Arrays.asList("555-6654", "555-3242")); using java 8 get a list with all phone numbers in the map | G9: List<String> phones = people.values().stream() .flatMap(Collection::stream) .collect(Collectors.toList()); System.out.println(phones);

Sheet Changelog
A1: Date | B1: Version | C1: Implementor | D1: Change
A2: 43126 | B2: 4.11.1 | C2: Mikhail Lavoshnikov | D2: Corrected drop-down list values for "Communication in English" field (Overview!B4)
A3: 43126 | B3: 4.11.1 | C3: Mikhail Lavoshnikov | D3: Corrected maximum score values in hidden column D (Java!D:D)
A4: 43126 | B4: 4.11.1 | C4: Mikhail Lavoshnikov | D4: Added numbering for Java sections
A5: 43170 | B5: 5.1.0 | C5: Oleksii Kvitsynskyi | D5: Testing theory removed
A6: 43170 | B6: 5.1.0 | C6: Oleksii Kvitsynskyi | D6: Added descriptions for grades (junior, regular, etc.)
A7: 43170 | B7: 5.1.0 | C7: Oleksii Kvitsynskyi | D7: Moved changelog to a new tab
A8: 43170 | B8: 5.1.0 | C8: Oleksii Kvitsynskyi | D8: Removed mandatory question for REST
A9: 43170 | B9: 5.1.0 | C9: Oleksii Kvitsynskyi | D9: Removed mandatory mark from all sections not related to core Java (Spring, Hibernate, UNIX, SQL)
A10: 43170 | B10: 5.1.0 | C10: Oleksii Kvitsynskyi | D10: Disclaimer about mandatory sections addede
A11: 43170 | B11: 5.1.0 | C11: Oleksii Kvitsynskyi | D11: Added question about different automated testing types from cross-account, change questions structure based on Michal Kordas proposal
A12: 43170 | B12: 5.1.0 | C12: Oleksii Kvitsynskyi | D12: Added 3 more sections from cross-account
A13: 43213 | B13: 5.1.1 | C13: Roman Torsten | D13: Fixed incorrect link that result in Libre office incompatibility
... A37: 44879 | B37: 8.3.1 | C37: Oleksii Kvitsynskyi | D37: Added Cloud section, separated Spring Boot as a separate section, removed "Typical web applications vulnerabilities and prevention" section

Sheet Technical
A1: Min | B1: Max | C1: Seniority | E1: Expience
A2: 0.01 | B2: 1.33 | C2: insufficient | E2: not assessed
A3: 1.34 | B3: 2 | C3: junior | E3: Yes
A4: 2.01 | B4: 2.33 | C4: junior-regular | E4: No
A5: 2.5 | B5: 3 | C5: regular
A6: 3.01 | B6: 3.5 | C6: regular-senior
A7: 3.51 | B7: 4 | C7: senior
A8: 4.01 | B8: 5 | C8: expert
